Traceback (most recent call last):
  File "/Users/antonponomarev/PycharmProjects/pythonProject3/venv/lib/python3.8/site-packages/aiohttp/client_reqrep.py", line 625, in write_bytes
    await self.body.write(writer)
  File "/Users/antonponomarev/PycharmProjects/pythonProject3/venv/lib/python3.8/site-packages/aiohttp/multipart.py", line 906, in write
    await part.write(writer)
  File "/Users/antonponomarev/PycharmProjects/pythonProject3/venv/lib/python3.8/site-packages/aiohttp/payload.py", line 441, in write
    chunk = await self._iter.__anext__()
  File "/Users/antonponomarev/PycharmProjects/pythonProject3/venv/lib/python3.8/site-packages/aiogram/types/input_file.py", line 103, in read
    async with aiofiles.open(self.path, "rb") as f:
  File "/Users/antonponomarev/PycharmProjects/pythonProject3/venv/lib/python3.8/site-packages/aiofiles/base.py", line 98, in __aenter__
    self._obj = await self._coro
  File "/Users/antonponomarev/PycharmProjects/pythonProject3/venv/lib/python3.8/site-packages/aiofiles/threadpool/__init__.py", line 94, in _open
    f = yield from loop.run_in_executor(executor, cb)
  File "/Library/Frameworks/Python.framework/Versions/3.8/lib/python3.8/concurrent/futures/thread.py", line 57, in run
    result = self.fn(*self.args, **self.kwargs)
FileNotFoundError: [Errno 2] No such file or directory: 'output_file'

The above exception was the direct cause of the following exception:

Traceback (most recent call last):
  File "/Users/antonponomarev/PycharmProjects/pythonProject3/venv/lib/python3.8/site-packages/aiogram/client/session/aiohttp.py", line 171, in make_request
    async with session.post(
  File "/Users/antonponomarev/PycharmProjects/pythonProject3/venv/lib/python3.8/site-packages/aiohttp/client.py", line 1187, in __aenter__
    self._resp = await self._coro
  File "/Users/antonponomarev/PycharmProjects/pythonProject3/venv/lib/python3.8/site-packages/aiohttp/client.py", line 601, in _request
    await resp.start(conn)
  File "/Users/antonponomarev/PycharmProjects/pythonProject3/venv/lib/python3.8/site-packages/aiohttp/client_reqrep.py", line 965, in start
    message, payload = await protocol.read()  # type: ignore[union-attr]
  File "/Users/antonponomarev/PycharmProjects/pythonProject3/venv/lib/python3.8/site-packages/aiohttp/streams.py", line 622, in read
    await self._waiter
aiohttp.client_exceptions.ClientOSError: [Errno 2] Can not write request body for https://api.telegram.org/bot6866729844:AAGcjszAoKRHA-rneEQYey6407L68KcIZz8/sendPhoto

During handling of the above exception, another exception occurred:

Traceback (most recent call last):
  File "/Users/antonponomarev/PycharmProjects/pythonProject3/venv/lib/python3.8/site-packages/aiogram/dispatcher/middlewares/error.py", line 25, in __call__
    return await handler(event, data)
  File "/Users/antonponomarev/PycharmProjects/pythonProject3/venv/lib/python3.8/site-packages/aiogram/dispatcher/middlewares/user_context.py", line 27, in __call__
    return await handler(event, data)
  File "/Users/antonponomarev/PycharmProjects/pythonProject3/venv/lib/python3.8/site-packages/aiogram/fsm/middleware.py", line 41, in __call__
    return await handler(event, data)
  File "/Users/antonponomarev/PycharmProjects/pythonProject3/venv/lib/python3.8/site-packages/aiogram/dispatcher/event/telegram.py", line 121, in trigger
    return await wrapped_inner(event, kwargs)
  File "/Users/antonponomarev/PycharmProjects/pythonProject3/venv/lib/python3.8/site-packages/aiogram/dispatcher/event/handler.py", line 43, in call
    return await wrapped()
  File "/Users/antonponomarev/PycharmProjects/pythonProject3/venv/lib/python3.8/site-packages/aiogram/dispatcher/dispatcher.py", line 276, in _listen_update
    return await self.propagate_event(update_type=update_type, event=event, **kwargs)
  File "/Users/antonponomarev/PycharmProjects/pythonProject3/venv/lib/python3.8/site-packages/aiogram/dispatcher/router.py", line 128, in propagate_event
    return await observer.wrap_outer_middleware(_wrapped, event=event, data=kwargs)
  File "/Users/antonponomarev/PycharmProjects/pythonProject3/venv/lib/python3.8/site-packages/aiogram/dispatcher/router.py", line 123, in _wrapped
    return await self._propagate_event(
  File "/Users/antonponomarev/PycharmProjects/pythonProject3/venv/lib/python3.8/site-packages/aiogram/dispatcher/router.py", line 156, in _propagate_event
    response = await router.propagate_event(update_type=update_type, event=event, **kwargs)
  File "/Users/antonponomarev/PycharmProjects/pythonProject3/venv/lib/python3.8/site-packages/aiogram/dispatcher/router.py", line 128, in propagate_event
    return await observer.wrap_outer_middleware(_wrapped, event=event, data=kwargs)
  File "/Users/antonponomarev/PycharmProjects/pythonProject3/venv/lib/python3.8/site-packages/aiogram/dispatcher/router.py", line 123, in _wrapped
    return await self._propagate_event(
  File "/Users/antonponomarev/PycharmProjects/pythonProject3/venv/lib/python3.8/site-packages/aiogram/dispatcher/router.py", line 148, in _propagate_event
    response = await observer.trigger(event, **kwargs)
  File "/Users/antonponomarev/PycharmProjects/pythonProject3/venv/lib/python3.8/site-packages/aiogram/dispatcher/event/telegram.py", line 121, in trigger
    return await wrapped_inner(event, kwargs)
  File "/Users/antonponomarev/PycharmProjects/pythonProject3/venv/lib/python3.8/site-packages/aiogram/dispatcher/event/handler.py", line 43, in call
    return await wrapped()
  File "/Users/antonponomarev/PycharmProjects/pythonProject3/handlers/generate_custom.py", line 87, in all_message
    await message.answer_photo(photo=photo)
  File "/Users/antonponomarev/PycharmProjects/pythonProject3/venv/lib/python3.8/site-packages/aiogram/methods/base.py", line 84, in emit
    return await bot(self)
  File "/Users/antonponomarev/PycharmProjects/pythonProject3/venv/lib/python3.8/site-packages/aiogram/client/bot.py", line 441, in __call__
    return await self.session(self, method, timeout=request_timeout)
  File "/Users/antonponomarev/PycharmProjects/pythonProject3/venv/lib/python3.8/site-packages/aiogram/client/session/base.py", line 257, in __call__
    return cast(TelegramType, await middleware(bot, method))
  File "/Users/antonponomarev/PycharmProjects/pythonProject3/venv/lib/python3.8/site-packages/aiogram/client/session/aiohttp.py", line 178, in make_request
    raise TelegramNetworkError(method=method, message=f"{type(e).__name__}: {e}")
aiogram.exceptions.TelegramNetworkError: HTTP Client says - ClientOSError: [Errno 2] Can not write request body for https://api.telegram.org/bot6866729844:AAGcjszAoKRHA-rneEQYey6407L68KcIZz8/sendPhoto
